{"uuid": "c5bb239d-9d20-4b6b-b9c1-0a7565099ec8", "children": ["b4079a6c-8a0e-477f-aca7-fe3982ee3570"], "befores": [{"name": "driver", "status": "broken", "statusDetails": {"message": "urllib3.exceptions.MaxRetryError: HTTPConnectionPool(host='localhost', port=4723): Max retries exceeded with url: /wd/hub/session (Caused by NewConnectionError('<urllib3.connection.HTTPConnection object at 0x102e092e8>: Failed to establish a new connection: [Errno 61] Connection refused',))\n", "trace": "  File \"/Users/luokai/.virtualenvs/UIautocn/lib/python3.6/site-packages/pluggy/callers.py\", line 187, in _multicall\n    res = hook_impl.function(*args)\n  File \"/Users/luokai/.virtualenvs/UIautocn/lib/python3.6/site-packages/_pytest/fixtures.py\", line 923, in pytest_fixture_setup\n    result = call_fixture_func(fixturefunc, request, kwargs)\n  File \"/Users/luokai/.virtualenvs/UIautocn/lib/python3.6/site-packages/_pytest/fixtures.py\", line 783, in call_fixture_func\n    res = fixturefunc(**kwargs)\n  File \"/Users/luokai/PycharmProjects/UIautocn/tests/android_test_case/conftest.py\", line 36, in driver\n    driver = webdriver.Remote(APPIUM_LOCAL_HOST_URL, desired_caps)\n  File \"/Users/luokai/.virtualenvs/UIautocn/lib/python3.6/site-packages/selenium/webdriver/remote/webdriver.py\", line 157, in __init__\n    self.start_session(capabilities, browser_profile)\n  File \"/Users/luokai/.virtualenvs/UIautocn/lib/python3.6/site-packages/selenium/webdriver/remote/webdriver.py\", line 252, in start_session\n    response = self.execute(Command.NEW_SESSION, parameters)\n  File \"/Users/luokai/.virtualenvs/UIautocn/lib/python3.6/site-packages/selenium/webdriver/remote/webdriver.py\", line 319, in execute\n    response = self.command_executor.execute(driver_command, params)\n  File \"/Users/luokai/.virtualenvs/UIautocn/lib/python3.6/site-packages/selenium/webdriver/remote/remote_connection.py\", line 374, in execute\n    return self._request(command_info[0], url, body=data)\n  File \"/Users/luokai/.virtualenvs/UIautocn/lib/python3.6/site-packages/selenium/webdriver/remote/remote_connection.py\", line 402, in _request\n    resp = http.request(method, url, body=body, headers=headers)\n  File \"/Users/luokai/.virtualenvs/UIautocn/lib/python3.6/site-packages/urllib3/request.py\", line 72, in request\n    **urlopen_kw)\n  File \"/Users/luokai/.virtualenvs/UIautocn/lib/python3.6/site-packages/urllib3/request.py\", line 150, in request_encode_body\n    return self.urlopen(method, url, **extra_kw)\n  File \"/Users/luokai/.virtualenvs/UIautocn/lib/python3.6/site-packages/urllib3/poolmanager.py\", line 326, in urlopen\n    response = conn.urlopen(method, u.request_uri, **kw)\n  File \"/Users/luokai/.virtualenvs/UIautocn/lib/python3.6/site-packages/urllib3/connectionpool.py\", line 670, in urlopen\n    **response_kw)\n  File \"/Users/luokai/.virtualenvs/UIautocn/lib/python3.6/site-packages/urllib3/connectionpool.py\", line 670, in urlopen\n    **response_kw)\n  File \"/Users/luokai/.virtualenvs/UIautocn/lib/python3.6/site-packages/urllib3/connectionpool.py\", line 670, in urlopen\n    **response_kw)\n  File \"/Users/luokai/.virtualenvs/UIautocn/lib/python3.6/site-packages/urllib3/connectionpool.py\", line 641, in urlopen\n    _stacktrace=sys.exc_info()[2])\n  File \"/Users/luokai/.virtualenvs/UIautocn/lib/python3.6/site-packages/urllib3/util/retry.py\", line 399, in increment\n    raise MaxRetryError(_pool, url, error or ResponseError(cause))\n"}, "start": 1563153471958, "stop": 1563153472006}], "start": 1563153471958, "stop": 1563153472518}