{"uuid": "a632e0b7-9a44-4514-b741-25fc18cf7a24", "children": ["459a6ea3-f829-4ad6-b90d-e3133db2acdc"], "befores": [{"name": "getDriver", "status": "broken", "statusDetails": {"message": "selenium.common.exceptions.WebDriverException: Message: An unknown server-side error occurred while processing the command. Original error: Could not find a connected Android device.\n\n", "trace": "  File \"/Users/luokai/.virtualenvs/UIautocn/lib/python3.6/site-packages/pluggy/callers.py\", line 187, in _multicall\n    res = hook_impl.function(*args)\n  File \"/Users/luokai/.virtualenvs/UIautocn/lib/python3.6/site-packages/_pytest/fixtures.py\", line 923, in pytest_fixture_setup\n    result = call_fixture_func(fixturefunc, request, kwargs)\n  File \"/Users/luokai/.virtualenvs/UIautocn/lib/python3.6/site-packages/_pytest/fixtures.py\", line 783, in call_fixture_func\n    res = fixturefunc(**kwargs)\n  File \"/Users/luokai/PycharmProjects/UIautocn/tests/android_test_case/conftest.py\", line 24, in getDriver\n    driver = webdriver.Remote(APPIUM_LOCAL_HOST_URL, desired_caps)\n  File \"/Users/luokai/.virtualenvs/UIautocn/lib/python3.6/site-packages/selenium/webdriver/remote/webdriver.py\", line 157, in __init__\n    self.start_session(capabilities, browser_profile)\n  File \"/Users/luokai/.virtualenvs/UIautocn/lib/python3.6/site-packages/selenium/webdriver/remote/webdriver.py\", line 252, in start_session\n    response = self.execute(Command.NEW_SESSION, parameters)\n  File \"/Users/luokai/.virtualenvs/UIautocn/lib/python3.6/site-packages/selenium/webdriver/remote/webdriver.py\", line 321, in execute\n    self.error_handler.check_response(response)\n  File \"/Users/luokai/.virtualenvs/UIautocn/lib/python3.6/site-packages/selenium/webdriver/remote/errorhandler.py\", line 242, in check_response\n    raise exception_class(message, screen, stacktrace)\n"}, "start": 1563185376430, "stop": 1563185397979}], "start": 1563185376430, "stop": 1563185398127}