{"uuid": "7e4a0da0-e4a3-4e48-bc24-e7d3bf9de9ab", "children": ["254df070-b5e0-4730-94c3-01ad0fbf48a7"], "befores": [{"name": "driver", "status": "broken", "statusDetails": {"message": "urllib3.exceptions.MaxRetryError: HTTPConnectionPool(host='localhost', port=4723): Max retries exceeded with url: /wd/hub/session (Caused by NewConnectionError('<urllib3.connection.HTTPConnection object at 0x10e867ba8>: Failed to establish a new connection: [Errno 61] Connection refused',))\n", "trace": "  File \"/Users/luokai/.virtualenvs/UIautocn/lib/python3.6/site-packages/pluggy/callers.py\", line 187, in _multicall\n    res = hook_impl.function(*args)\n  File \"/Users/luokai/.virtualenvs/UIautocn/lib/python3.6/site-packages/_pytest/fixtures.py\", line 923, in pytest_fixture_setup\n    result = call_fixture_func(fixturefunc, request, kwargs)\n  File \"/Users/luokai/.virtualenvs/UIautocn/lib/python3.6/site-packages/_pytest/fixtures.py\", line 783, in call_fixture_func\n    res = fixturefunc(**kwargs)\n  File \"/Users/luokai/PycharmProjects/UIautocn/tests/android_test_case/test_android_contacts.py\", line 28, in driver\n    driver = webdriver.Remote(APPIUM_LOCAL_HOST_URL, desired_caps)\n  File \"/Users/luokai/.virtualenvs/UIautocn/lib/python3.6/site-packages/appium/webdriver/webdriver.py\", line 144, in __init__\n    proxy\n  File \"/Users/luokai/.virtualenvs/UIautocn/lib/python3.6/site-packages/selenium/webdriver/remote/webdriver.py\", line 157, in __init__\n    self.start_session(capabilities, browser_profile)\n  File \"/Users/luokai/.virtualenvs/UIautocn/lib/python3.6/site-packages/appium/webdriver/webdriver.py\", line 219, in start_session\n    response = self.execute(RemoteCommand.NEW_SESSION, parameters)\n  File \"/Users/luokai/.virtualenvs/UIautocn/lib/python3.6/site-packages/selenium/webdriver/remote/webdriver.py\", line 319, in execute\n    response = self.command_executor.execute(driver_command, params)\n  File \"/Users/luokai/.virtualenvs/UIautocn/lib/python3.6/site-packages/selenium/webdriver/remote/remote_connection.py\", line 374, in execute\n    return self._request(command_info[0], url, body=data)\n  File \"/Users/luokai/.virtualenvs/UIautocn/lib/python3.6/site-packages/selenium/webdriver/remote/remote_connection.py\", line 397, in _request\n    resp = self._conn.request(method, url, body=body, headers=headers)\n  File \"/Users/luokai/.virtualenvs/UIautocn/lib/python3.6/site-packages/urllib3/request.py\", line 72, in request\n    **urlopen_kw)\n  File \"/Users/luokai/.virtualenvs/UIautocn/lib/python3.6/site-packages/urllib3/request.py\", line 150, in request_encode_body\n    return self.urlopen(method, url, **extra_kw)\n  File \"/Users/luokai/.virtualenvs/UIautocn/lib/python3.6/site-packages/urllib3/poolmanager.py\", line 326, in urlopen\n    response = conn.urlopen(method, u.request_uri, **kw)\n  File \"/Users/luokai/.virtualenvs/UIautocn/lib/python3.6/site-packages/urllib3/connectionpool.py\", line 670, in urlopen\n    **response_kw)\n  File \"/Users/luokai/.virtualenvs/UIautocn/lib/python3.6/site-packages/urllib3/connectionpool.py\", line 670, in urlopen\n    **response_kw)\n  File \"/Users/luokai/.virtualenvs/UIautocn/lib/python3.6/site-packages/urllib3/connectionpool.py\", line 670, in urlopen\n    **response_kw)\n  File \"/Users/luokai/.virtualenvs/UIautocn/lib/python3.6/site-packages/urllib3/connectionpool.py\", line 641, in urlopen\n    _stacktrace=sys.exc_info()[2])\n  File \"/Users/luokai/.virtualenvs/UIautocn/lib/python3.6/site-packages/urllib3/util/retry.py\", line 399, in increment\n    raise MaxRetryError(_pool, url, error or ResponseError(cause))\n"}, "start": 1562926714382, "stop": 1562926714418}], "start": 1562926714382, "stop": 1562926714837}